Workbook

Sheet EPI
A1: f
B2: CONTROLE EPI | G2: ✔ | H2: JAQ. | J2: CALÇ. | L2: BOTA | N2: LUVA | P2: BAL. | R2: CAP. | U2: ✔ | V2: JAQ. | X2: CALÇ. | Z2: BOTA | AB2: LUVA | AD2: BAL. | AF2: CAP. | AI2: EPI PRETO
B3: EFETIVO | C3: MILITAR | D3: FUNÇÃO | E3: SARAM | H3: =COUNTIF(H4:H107,"<>")-COUNTIF(H4:H107,"---") -> 45 | J3: =COUNTIF(J4:J107,"<>")-COUNTIF(J4:J107,"---") -> 45 | L3: =COUNTIF(L4:L107,"<>")-COUNTIF(L4:L107,"---") -> 34 | N3: =COUNTIF(N4:N107,"<>")-COUNTIF(N4:N107,"---") -> 31 | P3: =COUNTIF(P4:P107,"<>")-COUNTIF(P4:P107,"---") -> 34 | R3: =COUNTIF(R4:R107,"<>")-COUNTIF(R4:R107,"---") -> 35 | V3: =COUNTIF(V4:V107,"<>")-COUNTIF(V4:V107,"---") -> 25 | X3: =COUNTIF(X4:X107,"<>")-COUNTIF(X4:X107,"---") -> 26 | Z3: =COUNTIF(Z4:Z107,"<>")-COUNTIF(Z4:Z107,"---") -> 36 | AB3: =COUNTIF(AB4:AB107,"<>")-COUNTIF(AB4:AB107,"---") -> 37 | AD3: =COUNTIF(AD4:AD107,"<>")-COUNTIF(AD4:AD107,"---") -> 34 | AF3: =COUNTIF(AF4:AF107,"<>")-COUNTIF(AF4:AF107,"---") -> 32 | AI3: JAQ. | AK3: CALÇ. | AM3: BOTA | AO3: LUVA | AQ3: BAL | AS3: CAP
B4: INT. | C4: 2S RAFAEL | D4: CHEFE DE EQUIPE | E4: 433974-6 | G4: TRUE | H4: G | I4: 001 | J4: G | K4: 001 | L4: 41 | M4: 001 | N4: UN | O4: 001 | P4: UN | Q4: 001 | R4: UN | S4: 001 | U4: FALSE | V4: --- | X4: --- | Z4: --- | AB4: --- | AD4: --- | AF4: --- | AI4: GMM | AK4: GMM | AM4: GMM | AO4: GMM | AQ4: GMM | AS4: GMM
B5: INT. | C5: 2S KALLEB | D5: CHEFE DE EQUIPE | E5: 655476-8 | G5: TRUE | H5: P | I5: 002 | J5: P | K5: 002 | L5: 40 | M5: 002 | N5: UN | O5: 002 | P5: UN | Q5: 002 | R5: UN | S5: 002 | U5: FALSE | V5: --- | X5: --- | Z5: --- | AB5: --- | AD5: --- | AF5: --- | AI5: ESTOUE | AK5: ESTOUE | AM5: ESTOUE | AO5: ESTOUE | AQ5: ESTOUE | AS5: ESTOUE
B6: INT. | C6: 2S MATHEUS | D6: CHEFE DE EQUIPE | E6: 655458-0 | G6: TRUE | H6: M | I6: 003 | J6: M | K6: 003 | L6: 42 | M6: 003 | N6: UN | O6: 003 | P6: UN | Q6: 003 | R6: UN | S6: 003 | U6: FALSE | V6: --- | X6: --- | Z6: --- | AB6: --- | AD6: --- | AF6: --- | AI6: EM USO | AJ6: =H3 -> 45 | AK6: EM USO | AL6: =J3 -> 45 | AM6: EM USO | AN6: =L3 -> 34 | AO6: EM USO | AP6: =N3 -> 31 | AQ6: EM USO | AR6: =P3 -> 34 | AS6: EM USO | AT6: =R3 -> 35
B7: INT. | C7: 2S LUIZA | D7: CHEFE DE EQUIPE | E7: 660343-2 | G7: FALSE | H7: --- | J7: --- | L7: --- | N7: --- | P7: --- | R7: --- | U7: TRUE | V7: EG | W7: 141 | X7: XL | Y7: 141 | Z7: 44 | AA7: 141 | AB7: UN | AC7: 141 | AD7: UN | AE7: 141 | AF7: UN | AG7: 141 | AI7: P | AJ7: =COUNTIF(H4:H108,"P") -> 8 | AK7: P | AL7: =COUNTIF(J4:J108,"P") -> 6 | AM7: 39 | AN7: =COUNTIF(L4:L108,"39") -> 4
B8: INT. | C8: 2S SAMUEL | D8: CHEFE DE EQUIPE | E8: 610993-4 | G8: TRUE | H8: M | I8: 004 | J8: M | K8: 004 | L8: 41 | M8: 004 | N8: UN | O8: 004 | P8: UN | Q8: 004 | R8: UN | S8: 004 | U8: FALSE | V8: --- | X8: --- | Z8: --- | AB8: --- | AD8: --- | AF8: --- | AI8: M | AJ8: =COUNTIF(H4:H108,"M") -> 25 | AK8: M | AL8: =COUNTIF(J4:J108,"M") -> 28 | AM8: 40 | AN8: =COUNTIF(L4:L108,"40") -> 2
B9: INT. | C9: 2S DANIEL | D9: CHEFE DE EQUIPE | E9: 655618-3 | G9: TRUE | H9: XL | I9: 005 | J9: XL | K9: 005 | L9: 46 | M9: 005 | N9: --- | P9: UN | Q9: 005 | R9: UN | S9: 005 | U9: TRUE | V9: --- | X9: --- | Z9: --- | AB9: UN | AC9: 105 | AD9: --- | AF9: --- | AI9: G | AJ9: =COUNTIF(H4:H108,"G") -> 9 | AK9: G | AL9: =COUNTIF(J4:J108,"G") -> 9 | AM9: 41 | AN9: =COUNTIF(L4:L108,"41") -> 5
B10: INT. | C10: 2S EVANDER | D10: CHEFE DE EQUIPE | E10: 605795-0 | G10: TRUE | H10: P | I10: 006 | J10: M | K10: 006 | L10: 39 | M10: 006 | N10: UN | O10: 006 | P10: UN | Q10: 006 | R10: UN | S10: 006 | U10: FALSE | V10: --- | X10: --- | Z10: --- | AB10: --- | AD10: --- | AF10: --- | AI10: GG | AJ10: =COUNTIF(H4:H108,"GG") -> 1 | AK10: GG | AL10: =COUNTIF(J4:J108,"GG") -> 0 | AM10: 42 | AN10: =COUNTIF(L4:L108,"42") -> 9
B11: INT. | C11: 2S EMILLY REIS | D11: CHEFE DE EQUIPE | E11: 671498-6 | G11: TRUE | H11: M | I11: 007 | J11: M | K11: 007 | L11: 39 | M11: 007 | N11: UN | O11: 007 | P11: UN | Q11: 007 | R11: UN | S11: 007 | U11: FALSE | V11: --- | X11: --- | Z11: --- | AB11: --- | AD11: --- | AF11: --- | AI11: EG | AJ11: =COUNTIF(H4:H108,"EG") -> 0 | AK11: EG | AL11: =COUNTIF(J4:J108,"EG") -> 0 | AM11: 43 | AN11: =COUNTIF(L4:L108,"43") -> 3
B12: INT. | C12: 2S BARTELT | D12: CHEFE DE EQUIPE | E12: 448998-5 | G12: TRUE | H12: XL | I12: 008 | J12: XL | K12: 008 | L12: 46 | M12: 008 | N12: UN | O12: 008 | P12: UN | Q12: 008 | R12: UN | S12: 008 | U12: FALSE | V12: --- | X12: --- | Z12: --- | AB12: --- | AD12: --- | AF12: --- | AI12: XL | AJ12: =COUNTIF(H4:H108,"XL") -> 2 | AK12: XL | AL12: =COUNTIF(J4:J108,"XL") -> 2 | AM12: 44 | AN12: =COUNTIF(L4:L108,"44") -> 8
B13: INT. | C13: 3S G. FRANCO | D13: CHEFE DE EQUIPE | E13: 673201-1 | G13: TRUE | H13: P | I13: 009 | J13: M | K13: 009 | L13: 39 | M13: 009 | N13: UN | O13: 009 | P13: UN | Q13: 009 | R13: UN | S13: 009 | U13: FALSE | V13: --- | X13: --- | Z13: --- | AB13: --- | AD13: --- | AF13: --- | AM13: 45 | AN13: =COUNTIF(L4:L108,"45") -> 1
B14: INT. | C14: 3S PRATES | D14: MOTORISTA | E14: 695938-5 | G14: FALSE | H14: --- | J14: --- | L14: --- | N14: --- | P14: --- | R14: --- | U14: FALSE | V14: --- | X14: --- | Z14: --- | AB14: --- | AD14: --- | AF14: --- | AM14: 46 | AN14: =COUNTIF(L4:L108,"46") -> 2
B15: INT. | C15: 3S FRANÇA | D15: CHEFE DE EQUIPE | E15: 7246242 | G15: TRUE | H15: M | I15: 011 | J15: M | K15: 011 | L15: 41 | M15: 011 | N15: UN | O15: 011 | P15: UN | Q15: 011 | R15: UN | S15: 011 | U15: FALSE | V15: --- | X15: --- | Z15: --- | AB15: --- | AD15: --- | AF15: ---
B16: INT. | C16: 3S TEIXEIRA | D16: MOTORISTA | E16: 741548-6 | G16: FALSE | H16: --- | J16: --- | L16: --- | N16: --- | P16: --- | R16: --- | U16: FALSE | V16: --- | X16: --- | Z16: --- | AB16: --- | AD16: --- | AF16: --- | AI16: EPI AMARELO
B17: INT. | C17: 3S SOUZA | D17: MOTORISTA | E17: 741558-3 | G17: FALSE | H17: --- | J17: --- | L17: --- | N17: --- | P17: --- | R17: --- | U17: FALSE | V17: --- | X17: --- | Z17: --- | AB17: --- | AD17: --- | AF17: --- | AI17: JAQ. | AK17: CALÇ. | AM17: BOTA | AO17: LUVA | AQ17: BAL. | AS17: CAP.
B18: INT. | C18: 3S OLIVEIRA | D18: MOTORISTA | E18: 370582-0 | G18: TRUE | H18: P | I18: 014 | J18: P | K18: 014 | L18: 39 | M18: 014 | N18: UN | O18: 014 | P18: UN | Q18: 014 | R18: UN | S18: 014 | U18: FALSE | V18: --- | X18: --- | Z18: --- | AB18: --- | AD18: --- | AF18: --- | AI18: ESTOUE | AK18: ESTOUE | AM18: ESTOUE | AO18: ESTOUE | AQ18: ESTOUE | AS18: ESTOUE
B19: INT. | C19: 3S NICACIO | D19: CHEFE DE EQUIPE | E19: 738733-4 | G19: TRUE | H19: M | I19: 015 | J19: M | K19: 015 | L19: 42 | M19: 015 | N19: UN | O19: 015 | P19: UN | Q19: 015 | R19: UN | S19: 015 | U19: FALSE | V19: --- | X19: --- | Z19: --- | AB19: --- | AD19: --- | AF19: --- | AI19: EM USO | AJ19: =V3 -> 25 | AK19: EM USO | AL19: =X3 -> 26 | AM19: EM USO | AN19: =Z3 -> 36 | AO19: EM USO | AP19: =AB3 -> 37 | AQ19: EM USO | AR19: =AD3 -> 34 | AS19: EM USO | AT19: =AF3 -> 32
B20: INT. | C20: CB R. CUNHA | D20: MOTORISTA | E20: 415791-5 | G20: TRUE | H20: M | I20: 016 | J20: M | K20: 016 | L20: 44 | M20: 016 | N20: UN | O20: 016 | P20: UN | Q20: 016 | R20: UN | S20: 016 | U20: FALSE | V20: --- | X20: --- | Z20: --- | AB20: --- | AD20: --- | AF20: --- | AI20: P | AJ20: =COUNTIF($V4:V118,"P") -> 5 | AK20: P | AL20: =COUNTIF($X4:X108,"P") -> 4 | AM20: 39 | AN20: =COUNTIF(Z4:Z108,"39") -> 0
B21: INT. | C21: CB RUIZ | D21: MOTORISTA | E21: 759862-9 | G21: FALSE | H21: --- | J21: --- | L21: --- | N21: --- | P21: --- | R21: --- | U21: FALSE | V21: --- | X21: --- | Z21: --- | AB21: --- | AD21: --- | AF21: --- | AI21: G | AJ21: =COUNTIF($V4:V108,"G") -> 5 | AK21: G | AL21: =COUNTIF($X4:X108,"G") -> 4 | AM21: 41 | AN21: =COUNTIF(Z4:Z108,"41") -> 5
B22: INT. | C22: CB SANTOS | D22: MOTORISTA | E22: 420700-9 | G22: FALSE | H22: --- | J22: --- | L22: --- | N22: --- | P22: --- | R22: --- | U22: FALSE | V22: --- | X22: --- | Z22: --- | AB22: --- | AD22: --- | AF22: --- | AI22: GG | AJ22: =COUNTIF($V4:V108,"GG") -> 9 | AK22: GG | AL22: =COUNTIF($X4:X108,"GG") -> 12 | AM22: 42 | AN22: =COUNTIF(Z4:Z108,"42") -> 7
B23: INT. | C23: CB MANAILSON | D23: MOTORISTA | E23: 618905-9 | G23: FALSE | H23: --- | J23: --- | L23: --- | N23: --- | P23: --- | R23: --- | U23: FALSE | V23: --- | X23: --- | Z23: --- | AB23: --- | AD23: --- | AF23: --- | AI23: EG | AJ23: =COUNTIF($V4:$V108,"EG") -> 2 | AK23: EG | AL23: =COUNTIF($X4:X108,"EG") -> 1 | AM23: 43 | AN23: =COUNTIF(Z4:Z108,"43") -> 5
B24: INT. | C24: CB BELCHIOR | D24: RÁDIO OPERADOR | E24: 769388-5 | G24: FALSE | H24: --- | J24: --- | L24: --- | N24: --- | P24: --- | R24: --- | U24: FALSE | V24: --- | X24: --- | Z24: --- | AB24: --- | AD24: --- | AF24: --- | AI24: XL | AJ24: =COUNTIF($V4:V108,"XL") -> 0 | AK24: XL | AL24: =COUNTIF($X4:X108,"XL") -> 1 | AM24: 44 | AN24: =COUNTIF(Z4:Z108,"44") -> 12
B25: INT. | C25: CB GEISLER | D25: MOTORISTA | E25: 728113-7 | G25: FALSE | H25: --- | J25: --- | L25: --- | N25: --- | P25: --- | R25: --- | U25: FALSE | V25: --- | X25: --- | Z25: --- | AB25: --- | AD25: --- | AF25: --- | AM25: 45 | AN25: =COUNTIF(Z4:Z108,"45") -> 1
B26: INT. | C26: CB MARTINS | D26: RÁDIO OPERADOR | E26: 611019-3 | G26: FALSE | H26: --- | J26: --- | L26: --- | N26: --- | P26: --- | R26: --- | U26: TRUE | V26: M | W26: 144 | X26: M | Y26: 144 | Z26: 43 | AA26: 144 | AB26: UN | AC26: 144 | AD26: UN | AE26: 144 | AF26: UN | AG26: 144 | AM26: 46 | AN26: =COUNTIF(Z4:Z108,"46") -> 2
B27: INT. | C27: CB LEONARDO | D27: MOTORISTA | E27: 769304-4 | G27: FALSE | H27: --- | J27: --- | L27: --- | N27: --- | P27: --- | R27: --- | U27: TRUE | V27: GG | W27: 145 | X27: GG | Y27: 145 | Z27: 43 | AA27: 145 | AB27: UN | AC27: 145 | AD27: UN | AE27: 145 | AF27: UN | AG27: 145
B28: INT. | C28: CB DOS SANTOS | D28: COMBATENTE | E28: 769386-9 | G28: FALSE | H28: --- | J28: --- | L28: --- | N28: --- | P28: --- | R28: --- | U28: TRUE | V28: M | W28: 146 | X28: M | Y28: 146 | Z28: 41 | AA28: 146 | AB28: UN | AC28: 146 | AD28: UN | AE28: 146 | AF28: UN | AG28: 146
B29: INT. | C29: CB FINATTO | D29: MOTORISTA | E29: 437467-3 | G29: FALSE | H29: --- | J29: --- | L29: --- | N29: --- | P29: --- | R29: --- | U29: FALSE | V29: --- | X29: --- | Z29: --- | AB29: --- | AD29: --- | AF29: ---
B30: INT. | C30: CB WILLIAM | D30: COMBATENTE | E30: 769292-7 | G30: FALSE | H30: --- | J30: --- | L30: --- | N30: --- | P30: --- | R30: --- | U30: TRUE | V30: --- | W30: 147 | X30: G | Y30: 147 | Z30: 40 | AA30: 147 | AB30: UN | AC30: 147 | AD30: UN | AE30: 147 | AF30: UN | AG30: 147
B31: INT. | C31: CB HENZ | D31: COMBATENTE | E31: 769301-0 | G31: TRUE | H31: G | I31: 048 | J31: G | K31: 048 | L31: 42 | M31: 048 | N31: UN | O31: 048 | P31: UN | Q31: 048 | R31: UN | S31: 048 | U31: FALSE | V31: --- | X31: --- | Z31: --- | AB31: --- | AD31: --- | AF31: ---
B32: INT. | C32: CB MUNIZ | D32: COMBATENTE | E32: 769343-5 | G32: FALSE | H32: --- | J32: --- | L32: --- | N32: --- | P32: --- | R32: --- | U32: FALSE | V32: --- | X32: --- | Z32: --- | AB32: --- | AD32: --- | AF32: ---
B33: INT. | C33: CB IGOR SANTOS | D33: RESGATISTA | E33: 734354-0 | G33: FALSE | H33: --- | J33: --- | L33: --- | N33: --- | P33: --- | R33: --- | U33: TRUE | V33: P | W33: 150 | X33: P | Y33: 150 | Z33: 44 | AA33: 150 | AB33: UN | AC33: 150 | AD33: UN | AE33: 150 | AF33: UN | AG33: 150
B34: INT. | C34: CB NEEMIAS | D34: RÁDIO OPERADOR | E34: 769366-4 | G34: FALSE | H34: --- | J34: --- | L34: --- | N34: --- | P34: --- | R34: --- | U34: FALSE | V34: --- | X34: --- | Z34: --- | AB34: --- | AD34: --- | AF34: ---
B35: INT. | C35: S2 SALDÍVIA | D35: RESGATISTA | E35: 734416-3 | G35: TRUE | H35: M | I35: 017 | J35: M | K35: 017 | L35: 44 | M35: 017 | N35: UN | O35: 017 | P35: UN | Q35: 017 | R35: UN | S35: 017 | U35: FALSE | V35: --- | X35: --- | Z35: --- | AB35: --- | AD35: --- | AF35: ---
B36: INT. | C36: S2 ELIAS | D36: COMBATENTE | E36: 750895-6 | G36: TRUE | H36: M | I36: 019 | J36: M | K36: 019 | L36: 44 | M36: 019 | N36: UN | O36: 019 | P36: UN | Q36: 019 | R36: UN | S36: 019 | U36: FALSE | V36: --- | X36: --- | Z36: --- | AB36: --- | AD36: --- | AF36: ---
B37: INT. | C37: S2 PEDROSO | D37: COMBATENTE | E37: 754716-1 | G37: TRUE | H37: G | I37: 021 | J37: G | K37: 021 | L37: 43 | N37: UN | O37: 021 | P37: UN | Q37: 021 | R37: UN | S37: 021 | U37: FALSE | V37: --- | X37: --- | Z37: --- | AB37: --- | AD37: --- | AF37: ---
B38: INT. | C38: S2 CÉSAR FERREIRA | D38: COMBATENTE | E38: 763644-0 | G38: TRUE | H38: G | I38: 022 | J38: G | K38: 022 | L38: --- | N38: --- | P38: UN | Q38: 022 | R38: --- | S38: 022 | U38: TRUE | V38: --- | X38: --- | Z38: 46 | AA38: 122 | AB38: UN | AC38: 122 | AD38: --- | AF38: ---
B39: INT. | C39: S2 OTTO | D39: COMBATENTE | E39: 763606-7 | G39: TRUE | H39: M | I39: 052 | J39: M | K39: 052 | L39: --- | N39: --- | P39: --- | R39: --- | U39: TRUE | V39: --- | X39: --- | Z39: 44 | AA39: 152 | AB39: UN | AC39: 152 | AD39: UN | AE39: 152 | AF39: UN | AG39: 152
B40: INT. | C40: S2 CORDOVA | D40: COMBATENTE | E40: 763669-5 | G40: TRUE | H40: M | I40: 023 | J40: M | K40: 023 | L40: 43 | M40: 023 | N40: UN | O40: 023 | P40: UN | Q40: 023 | R40: UN | S40: 023 | U40: FALSE | V40: --- | X40: --- | Z40: --- | AB40: --- | AD40: --- | AF40: ---
...

Sheet CONSUMO E DURADOURO
B1: SETOR | C1: BMP | D1: SITUAÇÃO | E1: DOCUMENTO | F1: DESCRIÇÃO DO MATERIAL
B2: RESERVA | C2: 1442090 | D2: CONS. DURAD. | E2: ...............….. | F2: 1 | G2: Pulverizador De Fumaça Para Apicultor
B3: RESERVA | C3: 1442100 | D3: CONS. DURAD. | E3: ...............….. | F3: 1 | G3: Luvas De Pvc Forrada Co 70cm Na Cor Verde
B4: RESERVA | C4: 1442108 | D4: CONS. DURAD. | E4: ...............….. | F4: 4 | G4: Luvas De Pvc Forrada Co 46cm Na Cor Verde
B5: RESERVA | C5: 1442115 | D5: CONS. DURAD. | E5: ...............….. | F5: 2 | G5: Cinturão De Segurança Tipo Abdominal
B6: RESERVA | C6: 1442119 | D6: CONS. DURAD. | E6: ...............….. | F6: 3 | G6: Capa De Chuva Em Pvc T - 50
B7: ARMAZ. | C7: 1442127 | D7: CONS. DURAD. | E7: ...............….. | F7: 11 | G7: Bota Preta Em Borracha De Cano Médio
B8: RESERVA | C8: 1442131 | D8: CONS. DURAD. | E8: ...............….. | F8: 4 | G8: Luva De Raspa De Couro 20cm
B9: ARMAZ. | C9: 1442135 | D9: CONS. DURAD. | E9: ...............….. | F9: 3 | G9: Croque Com Cabo Telescópio Em 3m
B10: RESERVA | C10: 1442138 | D10: CONS. DURAD. | E10: ...............….. | F10: 1 | G10: Macacão Em Pvc Tipo Saneamento Grande
B11: RESERVA | C11: 1442147 | D11: CONS. DURAD. | E11: ...............….. | F11: 16 | G11: Adaptador De Rosca 2 ¹/2
B12: ARMAZ. | C12: 1442150 | D12: CONS. DURAD. | E12: ...............….. | F12: 15 | G12: Luva De Aproximação De Fogo
B13: RESERVA | C13: 1442153 | D13: CONS. DURAD. | E13: ...............….. | F13: 18 | G13: Tampão De 2 ¹/2
... B100: RESERVA | C100: 1693535 | D100: CONS. DURAD. | E100: ...............….. | F100: 2 | G100: Chave De Fenda 3/16pol Ou 5x100mm

Sheet EXTINTORES
B1: SETOR | C1: BMP | D1: SITUAÇÃO | E1: DOCUMENTO | F1: DESCRIÇÃO DO MATERIAL
B2: OREI DEP. | C2: 938082 | D2: DESCARREGADO | E2: SUBP. 5303 | F2: Extintor De Incêndio Tipo Emp-10l. (SISPAT: 33920042 - FCG: 3392)
B3: OREI DEP. | C3: 938083 | D3: DESCARREGADO | E3: SUBP. 5303 | F3: Extintor De Incêndio Tipo Emp-10l. (SISPAT: 33920043 - FCG: 3392)
B4: OREI DEP. | C4: 938084 | D4: DESCARREGADO | E4: SUBP. 5303 | F4: Extintor De Incêndio Tipo Emp-10l. (SISPAT: 33920044 - FCG: 3392)
B5: OREI DEP. | C5: 938085 | D5: DESCARREGADO | E5: SUBP. 5303 | F5: Extintor De Incêndio Tipo Emp-10l. (SISPAT: 33920045 - FCG: 3392)
B6: OREI DEP. | C6: 938086 | D6: DESCARREGADO | E6: SUBP. 5303 | F6: Extintor De Incêndio Tipo Emp-10l. (SISPAT: 33920046 - FCG: 3392)
B7: OREI DEP. | C7: 938087 | D7: DESCARREGADO | E7: SUBP. 5303 | F7: Extintor De Incêndio Tipo Emp-10l. (SISPAT: 33920040 - FCG: 3392)
B8: OREI DEP. | C8: 938088 | D8: DESCARREGADO | E8: SUBP. 5303 | F8: Extintor De Incêndio Tipo Emp-10l. (SISPAT: 33920041 - FCG: 3392)
B9: OREI DEP. | C9: 938089 | D9: DESCARREGADO | E9: SUBP. 5303 | F9: Extintor De Incêndio Tipo Emp-10l. (SISPAT: 33920047 - FCG: 3392)
B10: OREI DEP. | C10: 938090 | D10: DESCARREGADO | E10: SUBP. 5303 | F10: Extintor De Incêndio Tipo Emp-10l. (SISPAT: 33920048 - FCG: 3392)
B11: OREI DEP. | C11: 938091 | D11: DESCARREGADO | E11: SUBP. 5303 | F11: Extintor De Incêndio Tipo Emp-10l. (SISPAT: 33920049 - FCG: 3392)
B12: OREI DEP. | C12: 938092 | D12: DESCARREGADO | E12: SUBP. 5303 | F12: Extintor De Incêndio Tipo Emp-10l. (SISPAT: 33920050 - FCG: 3392)
B13: OREI DEP. | C13: 938093 | D13: DESCARREGADO | E13: SUBP. 5303 | F13: Extintor De Incêndio Tipo Emp-10l. (SISPAT: 33920051 - FCG: 3392)
... B1773: OREI DEP. | C1773: 1908518 | D1773: PERFEITO | E1773: ...............….. | F1773: Extintor De Incêndio Tipo Abc 06 Kg - Validade 05 Anos

Sheet PERMANENTE 
B1: SETOR | C1: 📋 | D1: ✔ | E1: BMP | F1: SITUAÇÃO | G1: DOCUMENTO | H1: DESCRIÇÃO DO MATERIAL
B2: ARMAZ. | C2: 1 | D2: TRUE | E2: 501202 | F2: PERFEITO | G2: ...............….. | H2: Estabilizador De Tensão Bmi , Bivolt, Mod. Microline Iii Ml1000b1 (SISPAT: 452136 - FCG: 18755 - Nº SÉRIE:DACTA2/2010-086)
B3: F 06 | C3: 1 | D3: TRUE | E3: 937117 | F3: PERFEITO | G3: ...............….. | H3: Transceptor Móvel Monocanal, Vhf/Fm, Faixa De Operação 148 A 174.999 Mhz, Potência De 45w,Marca Motorola, Acompanhado De Antena Com Cabo Coaxial Medidor 4.400mm, Microfone, Kit DeInstalação E Manual Técnico. (SISPAT: 9911 - FCG: 11105)
B4: F 08 | C4: 1 | D4: TRUE | E4: 937118 | F4: TROCA NOMEN. | G4: ...............….. | H4: Transceptor Móvel Monocanal, Vhf/Fm, Faixa De Operação 148 A 174.999 Mhz, Potência De 45w, Marca Motorola, Acompanhado De Antena Com Cabo Coaxial Medidor 4.400mm, Microfone, Kit DeInstalação E Manual Técnico. (SISPAT: 9912 - FCG: 11105)
B5: MANUTENÇÃO | C5: 1 | D5: TRUE | E5: 937119 | F5: TROCA NOMEN. | G5: ...............….. | H5: Transceptor Móvel Monocanal, Vhf/Fm, Faixa De Operação 148 A 174.999 Mhz, Potência De 45w, Marca Motorola, Acompanhado De Antena Com Cabo Coaxial Medidor 4.400mm, Microfone, Kit DeInstalação E Manual Técnico. (SISPAT: 9913 - FCG: 11105)
B6: MANUTENÇÃO | C6: 1 | D6: TRUE | E6: 937120 | F6: TROCA NOMEN. | G6: ...............….. | H6: Transceptor Móvel Monocanal, Vhf/Fm, Faixa De Operação 148 A 174.999 Mhz, Potência De 45w, Marca Motorola, Acompanhado De Antena Com Cabo Coaxial Medidor 4.400mm, Microfone, Kit DeInstalação E Manual Técnico. (SISPAT: 9914 - FCG: 11105)
B7: MANUTENÇÃO | C7: 1 | D7: TRUE | E7: 937121 | F7: TROCA NOMEN. | G7: ...............….. | H7: Transceptor Móvel Monocanal, Vhf/Fm, Faixa De Operação 148 A 174.999 Mhz, Potência De 45w, Marca Motorola, Acompanhado De Antena Com Cabo Coaxial Medidor 4.400mm, Microfone, Kit DeInstalação E Manual Técnico. (SISPAT: 9915 - FCG: 11105)
B8: MANUTENÇÃO | C8: 1 | D8: TRUE | E8: 937122 | F8: TROCA NOMEN. | G8: ...............….. | H8: Transceptor Fixo Monocanal, Vhf/Fm, Faixa De Operações 148 A 174.999mhz, Potência De 45w Com Fonte De Flutuação Marca Motorola. (SISPAT: 9919 - FCG: 11130)
B9: DOC | C9: --- | D9: TRUE | E9: 937142 | F9: DESCARREGADO | G9: PARTE 1241 | H9: Rádio Transceptor Móvel Vhf, Nº De Série 019nes0117, Motorola Completo. (SISPAT: 28665 - FCG: 13037)
B10: DOC | C10: 1 | D10: TRUE | E10: 937192 | F10: DESCARREGADO | G10: SUBP. 10469 | H10: Balança Eletrônica, De 150 Kg. (SISPAT: 258401 - FCG: 2584)
B11: MANUTENÇÃO | C11: 1 | D11: TRUE | E11: 937193 | F11: PERFEITO | G11: ...............….. | H11: Calibrador De Pneu De Parede De 0 Até 80 Libras. Marca Garagem. (SISPAT: 36440001 - FCG: 3644)
B12: DOC | C12: 1 | D12: TRUE | E12: 937228 | F12: TRANSFERIDO | G12: SUBP. 4228 | H12: Paquímetro Mytutoyo De 6 Pol. (SISPAT: 5151 - FCG: 3582)
B13: DOC | C13: --- | D13: TRUE | E13: 937244 | F13: DESCARREGADO | G13: SUBP. 4358 | H13: Equipamento De Teste Hidrostatico De Ampolas Completo. (SISPAT: 27238 - FCG: 16317)
B14: OREI DEP. | C14: 1 | D14: TRUE | E14: 937318 | F14: DESCARREGADO | G14: SUBP. 10469 | H14: Balança Eletrônica Digital, Capacidade De Ate 50 Kg, 110/220v. (SISPAT: 13973 - FCG: 9)
B15: OREI DEP. | C15: 1 | D15: TRUE | E15: 937328 | F15: DESCARREGADO | G15: SUBP. 10469 | H15: Balança De 25 Kg - Bancada 24 Cm/36 Cm Divisao 50g - Leitura Regua Mecanica, Modelo 250. (SISPAT: 7327 - FCG: 4124)
B16: OREI DEP. | D16: TRUE | E16: 937351 | F16: DESCARREGADO | G16: SUBP. 10468 | H16: Aparelho Telefônico Comum De Teclas Padrão Telebras. (SISPAT: 241626 - FCG: 2416)
B17: OREI DEP. | D17: TRUE | E17: 937352 | F17: DESCARREGADO | G17: SUBP. 10468 | H17: Aparelho Telefônico Comum De Teclas Padrão Telebras. (SISPAT: 241627 - FCG: 2416)
B18: DOC | C18: --- | D18: TRUE | E18: 937353 | F18: DESCARREGADO | G18: PARTE 1241 | H18: Aparelho Telefônico Comum De Teclas Padrão Telebras. (SISPAT: 241628 - FCG: 2416)
B19: OREI DEP. | D19: TRUE | E19: 937354 | F19: DESCARREGADO | G19: SUBP. 10468 | H19: Aparelho Telefônico Comum De Teclas Padrão Telebras. (SISPAT: 241629 - FCG: 2416)
B20: OREI DEP. | D20: TRUE | E20: 937771 | F20: DESCARREGADO | G20: SUBP. 10468 | H20: Aparelho De Fax, Sem Secretária E Com Corte Automático De Papel, 110v, Marca Sharp, Modelo Ux 66,N/S 17123443. (SISPAT: 19918 - FCG: 5187)
B21: DOC | C21: --- | D21: TRUE | E21: 937787 | F21: DESCARREGADO | G21: PARTE 1241 | H21: Conjunto De Laringofone. (SISPAT: 33540001 - FCG: 3354)
B22: DOC | C22: --- | D22: TRUE | E22: 937824 | F22: DESCARREGADO | G22: PARTE 1241 | H22: Conjunto De Laringofone. (SISPAT: 33540002 - FCG: 3354)
B23: DOC | C23: --- | D23: TRUE | E23: 937825 | F23: DESCARREGADO | G23: PARTE 1241 | H23: Conjunto De Laringofone. (SISPAT: 33540003 - FCG: 3354)
B24: DOC | C24: --- | D24: TRUE | E24: 937826 | F24: DESCARREGADO | G24: PARTE 1241 | H24: Conjunto De Laringofone. (SISPAT: 33540004 - FCG: 3354)
B25: DOC | C25: --- | D25: TRUE | E25: 937827 | F25: DESCARREGADO | G25: PARTE 1241 | H25: Conjunto De Laringofone. (SISPAT: 33540005 - FCG: 3354)
B26: DOC | C26: --- | D26: TRUE | E26: 937828 | F26: DESCARREGADO | G26: PARTE 1241 | H26: Conjunto De Laringofone. (SISPAT: 33540006 - FCG: 3354)
B27: DOC | C27: --- | D27: TRUE | E27: 937829 | F27: DESCARREGADO | G27: PARTE 1241 | H27: Rádio Transceptor Vhf Portátil, Completo. (SISPAT: 33550001 - FCG: 3355)
B28: DOC | C28: --- | D28: TRUE | E28: 937830 | F28: DESCARREGADO | G28: PARTE 1241 | H28: Rádio Transceptor Vhf Portátil, Completo. (SISPAT: 33550002 - FCG: 3355)
B29: DOC | C29: --- | D29: TRUE | E29: 937831 | F29: DESCARREGADO | G29: PARTE 1241 | H29: Rádio Transceptor Vhf Portátil, Completo. (SISPAT: 33550003 - FCG: 3355)
B30: DOC | C30: --- | D30: TRUE | E30: 937832 | F30: DESCARREGADO | G30: PARTE 1241 | H30: Rádio Transceptor Vhf Portátil, Completo. (SISPAT: 33550004 - FCG: 3355)
B31: DOC | C31: --- | D31: TRUE | E31: 937833 | F31: DESCARREGADO | G31: PARTE 1241 | H31: Rádio Transceptor Vhf Portátil, Completo. (SISPAT: 33550005 - FCG: 3355)
B32: DOC | C32: --- | D32: FALSE | E32: 937834 | F32: DESCARREGADO | G32: PARTE 1241 | H32: Rádio Transceptor Vhf Portátil, Completo. (SISPAT: 33550006 - FCG: 3355)
B33: DOC | C33: 3 | D33: TRUE | E33: 937875 | F33: TRANSFERIDO | G33: SUBP. 4228 | H33: Paquímetro Marca Mitutoyo. (SISPAT: 19308 - FCG: 3900)
B34: DOC | C34: 3 | D34: TRUE | E34: 937876 | F34: TRANSFERIDO | G34: SUBP. 4228 | H34: Torquimetro Estalo, Marca Raven, Modelo 2008, De 3kgf/Cm2 A 14kgf/Cm2. (SISPAT: 19309 - FCG: 3908)
B35: OREI DEP. | C35: 3 | D35: TRUE | E35: 937877 | F35: DESCARREGADO | G35: SUBP. 10469 | H35: Balança De Precisao Eletroânica, Com Capacidade Para 6kg, Divisao Minima De 2g, Plataforma Medindo 270 X 235mm, Com Indicador Digital Modelo Id - 900. (SISPAT: 19314 - FCG: 3920)
B36: PAJÉ | C36: 3 | D36: TRUE | E36: 937882 | F36: REGISTRO | G36: ...............….. | H36: Condicionador De Ar Split Com Capacidade De 18000 Btus, 220v, Ar Quente E Frio, Com ControleRemoto. (SISPAT: 19410001 - FCG: 1941)
B37: DOC | C37: --- | D37: TRUE | E37: 937942 | F37: DESCARREGADO | G37: PARTE 1241 | H37: Motosserra Completa. (SISPAT: 33560001 - FCG: 3356)
B38: ARMAZ. | C38: 3 | D38: TRUE | E38: 937946 | F38: PROCES. DESCARG. | G38: SUB 13715 | H38: Motoserra Nº 138478590, Marca Sthil Mod. Ts350, Com Kit De Corte Para Metais. (SISPAT: 14888 - FCG: 327)
B39: OREI DEP. | C39: 3 | D39: TRUE | E39: 937950 | F39: DESCARREGADO | G39: SUBP. 10469 | H39: Pulverizador De Fumaça Para Apicultor, Sc Brasil. (SISPAT: 156501 - FCG: 1565
B40: OREI DEP. | C40: 4 | D40: TRUE | E40: 938021 | F40: CONDENADO | G40: ...............….. | H40: Poltrona De Auditório Com Prancheta. (SISPAT: 970003 - FCG: 970)
...

Sheet CONTROLE BMP
B2: TOTAL BMP | C2: =SUM(C3:C5)-SUM(C11:C12) -> 1032 | D2: HISTÓRICO BMP | E2: =SUM(C3:C5) -> 2432
B3: PERMANENTE | C3: =COUNTIF('PERMANENTE '!F2:F562,"*") -> 561 | E3: =C3/$E$2 -> 0.23067434
B4: CONS. DURAD. | C4: =COUNTIF('CONSUMO E DURADOURO'!D2:D100,"*") -> 99 | E4: =C4/$E$2 -> 0.040707237
B5: EXTINTORES | C5: =COUNTIF(EXTINTORES!D2:D1773,"*") -> 1772 | E5: =C5/$E$2 -> 0.72861842
B6: AVARIADO | C6: =COUNTIF('PERMANENTE '!F:F,"AVARIADO")+COUNTIF(EXTINTORES!D:D,"AVARIADO") -> 7 | D6: AVARIADO | E6: =C6/$E$2 -> 0.0028782895
B7: CONDENADO | C7: =COUNTIF('PERMANENTE '!F:F,"CONDENADO")+COUNTIF(EXTINTORES!D:D,"CONDENADO") -> 67 | D7: CONDENADO | E7: =C7/$E$2 -> 0.027549342
B8: PROCES. DESCARG. | C8: =COUNTIF('PERMANENTE '!F:F,"PROCES. DESCARG.")+COUNTIF(EXTINTORES!D:D,"PROCES. DESCARG.") -> 29 | D8: PROCES. DESCARG. | E8: =C8/$E$2 -> 0.011924342
B9: EM TRANSF. | C9: =COUNTIF('PERMANENTE '!F:F,"EM TRANSF.")+COUNTIF(EXTINTORES!D:D,"EM TRANSF.") -> 1 | D9: EM TRANSF. | E9: =C9/$E$2 -> 0.00041118421
B10: Ñ ENCONTRADO | C10: =COUNTIF('PERMANENTE '!F:F,"Ñ ENCONTRADO")+COUNTIF(EXTINTORES!D:D,"Ñ ENCONTRADO") -> 1 | D10: Ñ ENCONTRADO | E10: =C10/$E$2 -> 0.00041118421
B11: DESCARREGADO | C11: =COUNTIF('PERMANENTE '!F:F,"DESCARREGADO")+COUNTIF(EXTINTORES!D:D,"DESCARREGADO") -> 1396 | D11: SAÍDA | E11: =SUM(C11:C12)/$E$2 -> 0.57565789
B12: TRANSFERIDO | C12: =COUNTIF('PERMANENTE '!F:F,"TRANSFERIDO")+COUNTIF(EXTINTORES!D:D,"TRANSFERIDO") -> 4
B13: PERFEITO | C13: =COUNTIF('PERMANENTE '!F:F,"PERFEITO")+COUNTIF(EXTINTORES!D:D,"PERFEITO") -> 729 | D13: PERFEITO | E13: =SUM(C13:C20)/$E$2 -> 0.38157895
B14: AGUARDAN. CARGA | C14: =COUNTIF('PERMANENTE '!F:F,"AGUARDAN. CARGA")+COUNTIF(EXTINTORES!D:D,"AGUARDAN. CARGA") -> 0
B15: REGISTRO | C15: =COUNTIF('PERMANENTE '!F:F,"REGISTRO")+COUNTIF(EXTINTORES!D:D,"REGISTRO") -> 28
B16: OREI | C16: =COUNTIF('PERMANENTE '!F:F,"OREI")+COUNTIF(EXTINTORES!D:D,"OREI") -> 58
B17: TROCA NOMEN. | C17: =COUNTIF('PERMANENTE '!F:F,"TROCA NOMEN.")+COUNTIF(EXTINTORES!D:D,"TROCA NOMEN.") -> 8
B18: EMPRESTADO | C18: =COUNTIF('PERMANENTE '!F:F,"EMPRESTADO")+COUNTIF(EXTINTORES!D:D,"EMPRESTADO") -> 0
B19: ITEM DESCARACTZ | C19: =COUNTIF('PERMANENTE '!F:F,"ITEM DESCARACTZ")+COUNTIF(EXTINTORES!D:D,"ITEM DESCARACTZ") -> 6
B20: CONS. DURAD. | C20: =COUNTIF('CONSUMO E DURADOURO'!D:D,"CONS. DURAD.")+COUNTIF(EXTINTORES!D:D,"CONS. DURAD.") -> 99
